Workbook

Sheet OTR
C1: APR | D1: MEI | E1: NEW
A2: TYPE | C2: Jember | D2: Jember | E2: Jember
A3: NF11T14C01 M/T | B3: Revo Fit | C3: 16709000 | D3: 16709000 | E3: =Sheet3!I3 -> 19475000
A4: NF11T14C03 M/T | B4: Revo X | C4: 18415000 | D4: 18415000 | E4: =Sheet3!I4 -> 21175000
A5: G2A02N02S3 M/T | B5: Supra X 125 Sp | C5: 19935000 | D5: 19935000 | E5: =Sheet3!I5 -> 22725000
A6: G2A02Q02S3 M/T | B6: Supra X 125 CW | C6: 21024000 | D6: 21024000 | E6: =Sheet3!I6 -> 23800000
A7: G2E02R21M1 M/T | B7: GTR 150 Sporty | C7: 26211000 | D7: 26211000 | E7: =Sheet3!I7 -> 28975000
A8: G2E02R21M1A M/T | B8: GTR 150 Exc | C8: 26463000 | D8: 26463000 | E8: =Sheet3!I8 -> 29225000
A9: D1B02N26S3 A/T | B9: BeAT Sporty CW | C9: 18348000 | D9: 18348000
A10: D1B02N12S3 A/T | B10: BeAT Sporty CBS | C10: 18558000 | D10: 18558000
A11: D1B02N13S3 A/T | B11: BeAT Sporty CBS ISS | C11: 19033000 | D11: 19033000
A12: D1I02N27S4 A/T | B12: BeAT Street | C12: 19022000 | D12: 19022000
A13: F1C02N28S2A A/T | B13: Scoopy Stylish | C13: 21208000 | D13: 21208000
A14: F1C02N28S2B A/T | B14: Scoopy Sporty | C14: 21208000 | D14: 21208000
A15: A1F02N36S2 A/T | B15: Vario 125 CBS | C15: 22960000 | D15: 23311000
A16: A1F02N37S2 A/T | B16: Vario 125 CBS ISS | C16: 23895000 | D16: 24247000
A17: V1J02Q32S2 A/T | B17: PCX 150 CBS | C17: 31022000 | D17: 31022000
A18: V1J02Q33S2 A/T | B18: PCX 150 ABS | C18: 33992000 | D18: 33992000
A19: NSS250AJJ IN A/T | B19: Forza | C19: 86436500 | D19: 86436500 | E19: =Sheet3!I84 -> 94325000
A20: B5D02K29M3 M/T | B20: CB 150 Verza Sp | C20: 22277000 | D20: 22277000 | E20: =Sheet3!I49 -> 26050000
A21: B5D02M29M3 M/T | B21: CB 150 Verza CW | C21: 22933000 | D21: 22933000 | E21: =Sheet3!I50 -> 26750000
A22: A5C02R37S1 M/T | B22: CB150R (BK) | C22: 29068000 | D22: 29068000
A23: A5C02R37S1A M/T | B23: CB150R (BK WH) | C23: 30168000 | D23: 30168000
A24: P5E02R22M2 M/T | B24: CBR150R Std (BK) | C24: 36814000 | D24: 36814000
A25: P5E02R22M2A M/T | B25: CBR150R Std (RD) | C25: 37514000 | D25: 37514000
A26: P5E02R40M2 M/T | B26: CBR150R ABS (BK) | C26: 40814000 | D26: 40814000
A27: P5E02R40M2A M/T | B27: CBR150R ABS (RD) | C27: 41514000 | D27: 41514000
A28: P5E02R40M2B M/T | B28: CBR150R ABS (Repsol) | C28: 41714000 | D28: 41714000
A29: T4G02T31S1 M/T | B29: CRF150L | C29: 36201000 | D29: 36251000 | E29: =Sheet3!I58 -> 38675000
A30: R5F04R25S1A M/T / R5F04R25L1A M/T | B30: CBR250RR Std (BK) Black Freedom | C30: 62358000 | D30: 62358000 | E30: =Sheet3!I71 -> 79575000
A31: R5F04R25S1 M/T / R5F04R25S1B M/T / R5F04R25L1 M/T | B31: CBR250RR Std (BK) | C31: 67183000 | D31: 67183000 | E31: =Sheet3!I70 -> 74725000
A32: R5F04R25S1C M/T | B32: CBR250RR Std (RD RC) | C32: 67783000 | D32: 67783000
A33: R5F04R24S1 M/T / R5F04R24S1A M/T / R5F04R24L1 M/T | B33: CBR250RR ABS (BK MH) | C33: 74249000 | D33: 74249000 | E33: 74735000
A34: R5F04R24S1B M/T / R5F04R24L1A M/T | B34: CBR250RR ABS (BL) | C34: 74854000 | D34: 74854000 | E34: =Sheet3!I72 -> 87825000
A35: CRF250RLJ IN M/T | B35: CRF250 Rally | C35: 89535000 | D35: 89535000 | E35: =Sheet3!I80 -> 96250000
A36: C125K IN M/T | B36: Super Cub 125 | C36: 74501000 | D36: 74501000 | E36: =Sheet3!I82 -> 79575000
A37: C1M02N41L0 A/T | B37: Genio CBS BK | C37: 20465000 | D37: 20815000 | E37: =Sheet3!I13 -> 22300000
B38: Genio CBS PH/PD | E38: =Sheet3!I14 -> 22500000
A39: C1M02N42L0 A/T | B39: Genio CBS ISS | C39: 21014000 | D39: 21364000 | E39: =Sheet3!I15 -> 22850000
A40: X1N02Q43LO A/T | B40: ADV150 CBS | C40: 36155500 | D40: 36155500
...

Sheet Sheet3
C1: 46114
C2: Type | E2: Kode MPM | G2: Bondowoso | H2: Situbondo | I2: Jember | J2: Banyuwangi
B3: 1 | C3: R2B02K01L2Z M/T | D3: REVO FIT | E3: GBZ | G3: 19425000 | H3: 19325000 | I3: 19475000 | J3: 19375000
B4: 2 | C4: R2B02M01L2Z M/T | D4: REVO X | E4: GDZ | G4: 21125000 | H4: 21025000 | I4: 21175000 | J4: 21075000
B5: 3 | C5: G2A02N02L4Z M/T | D5: SUPRA X 125 SW | E5: GEZ | G5: 22675000 | H5: 22575000 | I5: 22725000 | J5: 22625000
B6: 4 | C6: G2A02Q02L4Y M/T | D6: SUPRA X 125 CW | E6: GFY | G6: 23750000 | H6: 23650000 | I6: 23800000 | J6: 23750000
B7: 5 | C7: G2E02R21M1E M/T | D7: NEW SUPRA GTR150 SPORTY | E7: HJE | G7: 28875000 | H7: 28625000 | I7: 28975000 | J7: 28875000
B8: 6 | C8: G2E02R21M1AF M/T | D8: NEW SUPRA GTR150 XCLUSIVE | E8: HJF | G8: 29125000 | H8: 28875000 | I8: 29225000 | J8: 29125000
B9: 7 | C9: H1B02N41L1Y A/T | D9: BEAT SPORTY CBS | E9: MJW | G9: 21150000 | H9: 21050000 | I9: 21250000 | J9: 21150000
B10: 8 | C10: H1B02N42L1Y A/T | D10: BEAT SPORTY CBS ISS DELUXE | E10: MKW | G10: 22050000 | H10: 21950000 | I10: 22150000 | J10: 22050000
B11: 9 | C11: H1B0ZN42L1AY A/T | D11: BEAT SPORTY DLX SMART KEY | E11: MLW | G11: 22600000 | H11: 22500000 | I11: 22700000 | J11: 22600000
B12: 10 | C12: H1B02N53L1X A/T | D12: BEAT STREET | E12: MMW | G12: 22050000 | H12: 21950000 | I12: 22150000 | J12: 22050000
B13: 11 | C13: C1M02N41S2Z A/T | D13: GENIO CBS (BK) | E13: LYW | G13: 22200000 | H13: 22000000 | I13: 22300000 | J13: 22200000
B14: 12 | C14: C1M02N41S2Y A/T | D14: GENIO CBS (PH/PD) | E14: LYX | G14: 22400000 | H14: 22200000 | I14: 22500000 | J14: 22400000
... B19: 17 | C19: F1C02N47L2AX A/T | D19: SCOOPY STYLISH | E19: MSV | G19: 25625000 | H19: 25525000 | I19: 25675000 | J19: 25625000
B20: 18 | C20: F1C02N47L2AX A/T | D20: SCOOPY X KUROMI | E20: MSK
B21: 19 | C21: L1F02N36S4Z A/T | D21: VARIO 125 CBS | E21: MCY | G21: 25625000 | H21: 25575000 | I21: 25725000 | J21: 25625000
B22: 20 | C22: L1F02N37S4Z A/T | D22: VARIO 125 CBS ISS | E22: MDY | G22: 27625000 | H22: 27525000 | I22: 27675000 | J22: 27575000
B23: 21 | C23: L1F02N36L2Z A/T | D23: New VARIO 125 CBS | E23: NDZ | G23: 25900000 | H23: 25850000 | I23: 26000000 | J23: 25900000
B24: 22 | C24: L1F02N37L2Z A/T | D24: New VARIO 125 CBS ISS | E24: NEZ | G24: 27925000 | H24: 27825000 | I24: 27975000 | J24: 27875000
B25: 23 | C25: L1F02N53L2Z A/T | D25: New VARIO 125 Street | E25: NFZ | G25: 28450000 | H25: 28350000 | I25: 28500000 | J25: 28400000
B26: 24 | C26: L1F02N53L2Z A/T | D26: New VARIO 125 Street + Visor | E26: NFZ | G26: 28575000 | H26: 28475000 | I26: 28625000 | J26: 28525000
B27: 25 | C27: M1K03M32L0Z A/T | D27: STYLO 160 CBS | E27: MFX | G27: 31000000 | H27: 30950000 | I27: 31100000 | J27: 31000000
B28: 26 | C28: M1K03Q33L0Z A/T | D28: STYLO 160 ABS | E28: MGX | G28: 34050000 | H28: 33950000 | I28: 34100000 | J28: 34050000
B29: 27 | C29: M1K03Q33L0Z A/T | D29: STYLO 160 ABS SPECIAL COLOR | E29: MGW | G29: 35650000 | H29: 35550000 | I29: 35700000 | J29: 35650000
B30: 28 | C30: X1H02N32S1R A/T | D30: VARIO 160 CBS (BK/RD/BL) | E30: LVV | G30: 29400000 | H30: 29350000 | I30: 29500000 | J30: 29450000
B31: 29 | C31: X1H02N32S1AS A/T | D31: VARIO 160 CBS (BK/WH) | E31: LVW | G31: 29650000 | H31: 29600000 | I31: 29750000 | J31: 29700000
B32: 30 | C32: L1K02Q33S1Q A/T | D32: VARIO 160 ABS | E32: LWR | G32: 32400000 | H32: 32350000 | I32: 32500000 | J32: 32450000
... B76: 74 | C76: ST125ASY IN M/T | D76: ST125 DAX | E76: JZY | G76: 82975000 | H76: 82975000 | I76: 82975000 | J76: 82975000
B77: 75 | C77: Z125MANZ 2IN M/T | D77: Z125 MONKEY
B78: 76 | C78: Z125MAS IN M/T | D78: New Z125 MONKEY | E78: JYY | G78: 87425000 | H78: 87425000 | I78: 87425000 | J78: 87425000
B79: 77 | C79: CRF250LPZ IN M/T | D79: CRF250L | E79: JTX | G79: 86575000 | H79: 86575000 | I79: 86575000 | J79: 86575000
B80: 78 | C80: CRF250LRPY IN M/T | D80: CRF250RALLY | E80: JTW | G80: 96250000 | H80: 96250000 | I80: 96250000 | J80: 96250000
B81: 79 | C81: CT125APZ IN M/T | D81: CT125 | E81: AZZ | G81: 82475000 | H81: 82475000 | I81: 82475000 | J81: 82475000
B82: 80 | C82: C125SW IN M/T | D82: Super CUB | E82: AMW | G82: 79575000 | H82: 79575000 | I82: 79575000 | J82: 79575000
B83: 81 | C83: C125SX 2IN M/T | D83: Super CUB 2 IN 1 | E83: AMX | G83: 79575000 | H83: 79575000 | I83: 79575000 | J83: 79575000
B84: 82 | C84: NSS250APZ IN A/T | D84: FORZA | E84: FBY | G84: 94325000 | H84: 94325000 | I84: 94325000 | J84: 94325000

Sheet  REVO X
A1: REVO X LP | B1: DP | C1: % DP | D1: JANGKA WAKTU
D2: 12 | E2: 18 | F2: 24 | G2: 30 | H2: 36
A3: =OTR!E4 -> 21175000 | B3: 2200000 | C3: =B3/$A$3 -> 0.1038961 | D3: 2157000 | E3: 1547000 | F3: 1256000 | G3: 1071000 | H3: 976000
B4: 2300000 | C4: =B4/$A$3 -> 0.10861865 | D4: 2147000 | E4: 1540000 | F4: 1250000 | G4: 1066000 | H4: 971000
B5: 2400000 | C5: =B5/$A$3 -> 0.1133412 | D5: 2137000 | E5: 1533000 | F5: 1244000 | G5: 1061000 | H5: 966000
B6: 2500000 | C6: =B6/$A$3 -> 0.11806375 | D6: 2127000 | E6: 1526000 | F6: 1238000 | G6: 1056000 | H6: 961000
B7: 2600000 | C7: =B7/$A$3 -> 0.1227863 | D7: 2117000 | E7: 1519000 | F7: 1232000 | G7: 1051000 | H7: 956000
B8: 2700000 | C8: =B8/$A$3 -> 0.12750885 | D8: 2107000 | E8: 1512000 | F8: 1226000 | G8: 1046000 | H8: 951000
B9: 2800000 | C9: =B9/$A$3 -> 0.1322314 | D9: 2097000 | E9: 1505000 | F9: 1220000 | G9: 1041000 | H9: 946000
B10: 2900000 | C10: =B10/$A$3 -> 0.13695396 | D10: 2087000 | E10: 1498000 | F10: 1214000 | G10: 1036000 | H10: 941000
B11: 3000000 | C11: =B11/$A$3 -> 0.14167651 | D11: 2077000 | E11: 1491000 | F11: 1208000 | G11: 1031000 | H11: 936000
B12: 3100000 | C12: =B12/$A$3 -> 0.14639906 | D12: 2067000 | E12: 1484000 | F12: 1202000 | G12: 1026000 | H12: 931000
B13: 3200000 | C13: =B13/$A$3 -> 0.15112161 | D13: 2057000 | E13: 1477000 | F13: 1196000 | G13: 1021000 | H13: 926000
B14: 3300000 | C14: =B14/$A$3 -> 0.15584416 | D14: 2047000 | E14: 1470000 | F14: 1190000 | G14: 1016000 | H14: 921000
B15: 3400000 | C15: =B15/$A$3 -> 0.16056671 | D15: 2037000 | E15: 1463000 | F15: 1184000 | G15: 1011000 | H15: 916000
... B60: 7900000 | C60: =B60/$A$3 -> 0.37308146 | D60: 1587000 | E60: 1148000 | F60: 914000 | G60: 786000 | H60: 691000
D61: 1577000 | E61: 1141000 | F61: 908000 | G61: 781000 | H61: 686000
D62: 1567000 | E62: 1134000 | F62: 902000 | G62: 776000 | H62: 681000
D63: 1557000 | E63: 1127000 | F63: 896000 | G63: 771000 | H63: 676000
D64: 1547000 | E64: 1120000 | F64: 890000 | G64: 766000 | H64: 671000
D65: 1537000 | E65: 1113000 | F65: 884000 | G65: 761000 | H65: 666000
D66: 1527000 | E66: 1106000 | F66: 878000 | G66: 756000 | H66: 661000
D67: 1517000 | E67: 1099000 | F67: 872000 | G67: 751000 | H67: 656000
D68: 1507000 | E68: 1092000 | F68: 866000 | G68: 746000 | H68: 651000
D69: 1497000 | E69: 1085000 | F69: 860000 | G69: 741000 | H69: 646000
D70: 1487000 | E70: 1078000 | F70: 854000 | G70: 736000 | H70: 641000
D71: 1477000 | E71: 1071000 | F71: 848000 | G71: 731000 | H71: 636000
D72: 1467000 | E72: 1064000 | F72: 842000 | G72: 726000 | H72: 631000
... D79: 1397000 | E79: 1015000 | F79: 800000 | G79: 691000 | H79: 596000

Sheet  REVO FIT FI  
A1: REVO FIT FI | B1: DP | C1: % DP | D1: JANGKA WAKTU
D2: 12 | E2: 18 | F2: 24 | G2: 30 | H2: 36 | I2: .
A3: =OTR!E3 -> 19475000 | B3: 2000000 | C3: =B3/$A$3 -> 0.10269576 | D3: 1985000 | E3: 1426000 | F3: 1160000 | G3: 990000 | H3: 863000
B4: 2100000 | C4: =B4/$A$3 -> 0.10783055 | D4: 1975000 | E4: 1419000 | F4: 1154000 | G4: 985000 | H4: 859000
B5: 2200000 | C5: =B5/$A$3 -> 0.11296534 | D5: 1965000 | E5: 1412000 | F5: 1148000 | G5: 980000 | H5: 855000
B6: 2300000 | C6: =B6/$A$3 -> 0.11810013 | D6: 1955000 | E6: 1405000 | F6: 1142000 | G6: 975000 | H6: 851000
B7: 2400000 | C7: =B7/$A$3 -> 0.12323492 | D7: 1945000 | E7: 1398000 | F7: 1136000 | G7: 970000 | H7: 847000
B8: 2500000 | C8: =B8/$A$3 -> 0.1283697 | D8: 1935000 | E8: 1391000 | F8: 1130000 | G8: 965000 | H8: 843000
B9: 2600000 | C9: =B9/$A$3 -> 0.13350449 | D9: 1925000 | E9: 1384000 | F9: 1124000 | G9: 960000 | H9: 839000
B10: 2700000 | C10: =B10/$A$3 -> 0.13863928 | D10: 1915000 | E10: 1377000 | F10: 1118000 | G10: 955000 | H10: 835000
B11: 2800000 | C11: =B11/$A$3 -> 0.14377407 | D11: 1905000 | E11: 1370000 | F11: 1112000 | G11: 950000 | H11: 831000
B12: 2900000 | C12: =B12/$A$3 -> 0.14890886 | D12: 1895000 | E12: 1363000 | F12: 1106000 | G12: 945000 | H12: 827000
B13: 3000000 | C13: =B13/$A$3 -> 0.15404365 | D13: 1885000 | E13: 1356000 | F13: 1100000 | G13: 940000 | H13: 823000
B14: 3100000 | C14: =B14/$A$3 -> 0.15917843 | D14: 1875000 | E14: 1349000 | F14: 1094000 | G14: 935000 | H14: 819000
B15: 3200000 | C15: =B15/$A$3 -> 0.16431322 | D15: 1865000 | E15: 1342000 | F15: 1088000 | G15: 930000 | H15: 815000
... B55: 7200000 | C55: =B55/$A$3 -> 0.36970475 | D55: 1465000 | E55: 1062000 | F55: 848000 | G55: 730000 | H55: 655000
D56: 1455000 | E56: 1055000 | F56: 842000 | G56: 725000 | H56: 651000
D57: 1445000 | E57: 1048000 | F57: 836000 | G57: 720000 | H57: 647000
D58: 1435000 | E58: 1041000 | F58: 830000 | G58: 715000 | H58: 643000
D59: 1425000 | E59: 1034000 | F59: 824000 | G59: 710000 | H59: 639000
D60: 1415000 | E60: 1027000 | F60: 818000 | G60: 705000 | H60: 635000
D61: 1405000 | E61: 1020000 | F61: 812000 | G61: 700000 | H61: 631000
D62: 1395000 | E62: 1013000 | F62: 806000 | G62: 695000 | H62: 627000
D63: 1385000 | E63: 1006000 | F63: 800000 | G63: 690000 | H63: 623000
D64: 1375000 | E64: 999000 | F64: 794000 | G64: 685000 | H64: 619000
D65: 1365000 | E65: 992000 | F65: 788000 | G65: 680000 | H65: 615000
D66: 1355000 | E66: 985000 | F66: 782000 | G66: 675000 | H66: 611000
D67: 1345000 | E67: 978000 | F67: 776000 | G67: 670000 | H67: 607000
... D74: 1275000 | E74: 929000 | F74: 734000 | G74: 635000 | H74: 579000

Sheet  SUPRA X FI SP  
A1: SUPRA X FI SP | B1: DP | C1: % DP | D1: JANGKA WAKTU
D2: 12 | E2: 18 | F2: 24 | G2: 30 | H2: 36 | I2: .
A3: =OTR!E5 -> 22725000 | B3: 2300000 | C3: =B3/$A$3 -> 0.10121012 | D3: 2300000 | E3: 1646000 | F3: 1338000 | G3: 1138000 | H3: 1037000
B4: 2400000 | C4: =B4/$A$3 -> 0.10561056 | D4: 2290000 | E4: 1639000 | F4: 1332000 | G4: 1133000 | H4: 1032000
B5: 2500000 | C5: =B5/$A$3 -> 0.110011 | D5: 2280000 | E5: 1632000 | F5: 1326000 | G5: 1128000 | H5: 1027000
B6: 2600000 | C6: =B6/$A$3 -> 0.11441144 | D6: 2270000 | E6: 1625000 | F6: 1320000 | G6: 1123000 | H6: 1022000
B7: 2700000 | C7: =B7/$A$3 -> 0.11881188 | D7: 2260000 | E7: 1618000 | F7: 1314000 | G7: 1118000 | H7: 1017000
B8: 2800000 | C8: =B8/$A$3 -> 0.12321232 | D8: 2250000 | E8: 1611000 | F8: 1308000 | G8: 1113000 | H8: 1012000
B9: 2900000 | C9: =B9/$A$3 -> 0.12761276 | D9: 2240000 | E9: 1604000 | F9: 1302000 | G9: 1108000 | H9: 1007000
B10: 3000000 | C10: =B10/$A$3 -> 0.1320132 | D10: 2230000 | E10: 1597000 | F10: 1296000 | G10: 1103000 | H10: 1002000
B11: 3100000 | C11: =B11/$A$3 -> 0.13641364 | D11: 2220000 | E11: 1590000 | F11: 1290000 | G11: 1098000 | H11: 997000
B12: 3200000 | C12: =B12/$A$3 -> 0.14081408 | D12: 2210000 | E12: 1583000 | F12: 1284000 | G12: 1093000 | H12: 992000
B13: 3300000 | C13: =B13/$A$3 -> 0.14521452 | D13: 2200000 | E13: 1576000 | F13: 1278000 | G13: 1088000 | H13: 987000
B14: 3400000 | C14: =B14/$A$3 -> 0.14961496 | D14: 2190000 | E14: 1569000 | F14: 1272000 | G14: 1083000 | H14: 982000
B15: 3500000 | C15: =B15/$A$3 -> 0.1540154 | D15: 2180000 | E15: 1562000 | F15: 1266000 | G15: 1078000 | H15: 977000
... B65: 8500000 | C65: =B65/$A$3 -> 0.3740374 | D65: 1680000 | E65: 1212000 | F65: 966000 | G65: 828000 | H65: 727000
D66: 1670000 | E66: 1205000 | F66: 960000 | G66: 823000 | H66: 722000
D67: 1660000 | E67: 1198000 | F67: 954000 | G67: 818000 | H67: 717000
D68: 1650000 | E68: 1191000 | F68: 948000 | G68: 813000 | H68: 712000
D69: 1640000 | E69: 1184000 | F69: 942000 | G69: 808000 | H69: 707000
D70: 1630000 | E70: 1177000 | F70: 936000 | G70: 803000 | H70: 702000
D71: 1620000 | E71: 1170000 | F71: 930000 | G71: 798000 | H71: 697000
D72: 1610000 | E72: 1163000 | F72: 924000 | G72: 793000 | H72: 692000
D73: 1600000 | E73: 1156000 | F73: 918000 | G73: 788000 | H73: 687000
D74: 1590000 | E74: 1149000 | F74: 912000 | G74: 783000 | H74: 682000
D75: 1580000 | E75: 1142000 | F75: 906000 | G75: 778000 | H75: 677000
D76: 1570000 | E76: 1135000 | F76: 900000 | G76: 773000 | H76: 672000
D77: 1560000 | E77: 1128000 | F77: 894000 | G77: 768000 | H77: 667000
... D84: 1490000 | E84: 1079000 | F84: 852000 | G84: 733000 | H84: 632000

Sheet  SUPRA X FI CW  
A1: SUPRA X FI CW | B1: DP | C1: % DP | D1: JANGKA WAKTU
D2: 12 | E2: 18 | F2: 24 | G2: 30 | H2: 36
A3: =OTR!E6 -> 23800000 | B3: 2400000 | C3: =B3/$A$3 -> 0.10084034 | D3: 2378000 | E3: 1703000 | F3: 1344000 | G3: 1177000 | H3: 1029000
B4: 2500000 | C4: =B4/$A$3 -> 0.10504202 | D4: 2368000 | E4: 1696000 | F4: 1339000 | G4: 1172000 | H4: 1025000
B5: 2600000 | C5: =B5/$A$3 -> 0.1092437 | D5: 2358000 | E5: 1689000 | F5: 1334000 | G5: 1167000 | H5: 1021000
B6: 2700000 | C6: =B6/$A$3 -> 0.11344538 | D6: 2348000 | E6: 1682000 | F6: 1329000 | G6: 1162000 | H6: 1017000
B7: 2800000 | C7: =B7/$A$3 -> 0.11764706 | D7: 2338000 | E7: 1675000 | F7: 1324000 | G7: 1157000 | H7: 1013000
B8: 2900000 | C8: =B8/$A$3 -> 0.12184874 | D8: 2328000 | E8: 1668000 | F8: 1319000 | G8: 1152000 | H8: 1009000
B9: 3000000 | C9: =B9/$A$3 -> 0.12605042 | D9: 2318000 | E9: 1661000 | F9: 1314000 | G9: 1147000 | H9: 1005000
B10: 3100000 | C10: =B10/$A$3 -> 0.1302521 | D10: 2308000 | E10: 1654000 | F10: 1309000 | G10: 1142000 | H10: 1001000
B11: 3200000 | C11: =B11/$A$3 -> 0.13445378 | D11: 2298000 | E11: 1647000 | F11: 1304000 | G11: 1137000 | H11: 997000
B12: 3300000 | C12: =B12/$A$3 -> 0.13865546 | D12: 2288000 | E12: 1640000 | F12: 1299000 | G12: 1132000 | H12: 993000
B13: 3400000 | C13: =B13/$A$3 -> 0.14285714 | D13: 2278000 | E13: 1633000 | F13: 1294000 | G13: 1127000 | H13: 989000
B14: 3500000 | C14: =B14/$A$3 -> 0.14705882 | D14: 2268000 | E14: 1626000 | F14: 1289000 | G14: 1122000 | H14: 985000
B15: 3600000 | C15: =B15/$A$3 -> 0.1512605 | D15: 2258000 | E15: 1619000 | F15: 1284000 | G15: 1117000 | H15: 981000
... B68: 8900000 | C68: =B68/$A$3 -> 0.37394958 | D68: 1728000 | E68: 1248000 | F68: 1019000 | G68: 852000 | H68: 769000
D69: 1718000 | E69: 1241000 | F69: 1014000 | G69: 847000 | H69: 765000
D70: 1708000 | E70: 1234000 | F70: 1009000 | G70: 842000 | H70: 761000
D71: 1698000 | E71: 1227000 | F71: 1004000 | G71: 837000 | H71: 757000
D72: 1688000 | E72: 1220000 | F72: 999000 | G72: 832000 | H72: 753000
D73: 1678000 | E73: 1213000 | F73: 994000 | G73: 827000 | H73: 749000
D74: 1668000 | E74: 1206000 | F74: 989000 | G74: 822000 | H74: 745000
D75: 1658000 | E75: 1199000 | F75: 984000 | G75: 817000 | H75: 741000
D76: 1648000 | E76: 1192000 | F76: 979000 | G76: 812000 | H76: 737000
D77: 1638000 | E77: 1185000 | F77: 974000 | G77: 807000 | H77: 733000
D78: 1628000 | E78: 1178000 | F78: 969000 | G78: 802000 | H78: 729000
D79: 1618000 | E79: 1171000 | F79: 964000 | G79: 797000 | H79: 725000
D80: 1608000 | E80: 1164000 | F80: 959000 | G80: 792000 | H80: 721000
... D87: 1538000 | E87: 1115000 | F87: 924000 | G87: 757000 | H87: 693000

Sheet  SUPRA GTR SPORTY  
A1: SUPRA GTR SPORTY | B1: DP | C1: % DP | D1: JANGKA WAKTU
D2: 12 | E2: 18 | F2: 24 | G2: 30 | H2: 36 | O2: =(I3-I4)*1.5 -> 0
A3: =OTR!E7 -> 28975000 | B3: 2900000 | C3: =B3/$A$3 -> 0.10008628 | D3: 2894000 | E3: 2067000 | F3: 1673000 | G3: 1419000 | H3: 1241000
B4: 3000000 | C4: =B4/$A$3 -> 0.10353753 | D4: 2884000 | E4: 2060000 | F4: 1667000 | G4: 1414000 | H4: 1237000
B5: 3100000 | C5: =B5/$A$3 -> 0.10698878 | D5: 2874000 | E5: 2053000 | F5: 1661000 | G5: 1409000 | H5: 1233000
B6: 3200000 | C6: =B6/$A$3 -> 0.11044003 | D6: 2864000 | E6: 2046000 | F6: 1655000 | G6: 1404000 | H6: 1229000
B7: 3300000 | C7: =B7/$A$3 -> 0.11389129 | D7: 2854000 | E7: 2039000 | F7: 1649000 | G7: 1399000 | H7: 1225000
B8: 3400000 | C8: =B8/$A$3 -> 0.11734254 | D8: 2844000 | E8: 2032000 | F8: 1643000 | G8: 1394000 | H8: 1221000
B9: 3500000 | C9: =B9/$A$3 -> 0.12079379 | D9: 2834000 | E9: 2025000 | F9: 1637000 | G9: 1389000 | H9: 1217000
B10: 3600000 | C10: =B10/$A$3 -> 0.12424504 | D10: 2824000 | E10: 2018000 | F10: 1631000 | G10: 1384000 | H10: 1213000
B11: 3700000 | C11: =B11/$A$3 -> 0.12769629 | D11: 2814000 | E11: 2011000 | F11: 1625000 | G11: 1379000 | H11: 1209000
B12: 3800000 | C12: =B12/$A$3 -> 0.13114754 | D12: 2804000 | E12: 2004000 | F12: 1619000 | G12: 1374000 | H12: 1205000
B13: 3900000 | C13: =B13/$A$3 -> 0.13459879 | D13: 2794000 | E13: 1997000 | F13: 1613000 | G13: 1369000 | H13: 1201000
B14: 4000000 | C14: =B14/$A$3 -> 0.13805004 | D14: 2784000 | E14: 1990000 | F14: 1607000 | G14: 1364000 | H14: 1197000
B15: 4100000 | C15: =B15/$A$3 -> 0.14150129 | D15: 2774000 | E15: 1983000 | F15: 1601000 | G15: 1359000 | H15: 1193000
... B85: 11100000 | C85: =B85/$A$3 -> 0.38308887 | D85: 2074000 | E85: 1493000 | F85: 1181000 | G85: 1009000 | H85: 913000
D86: 2064000 | E86: 1486000 | F86: 1175000 | G86: 1004000 | H86: 909000
D87: 2054000 | E87: 1479000 | F87: 1169000 | G87: 999000 | H87: 905000
D88: 2044000 | E88: 1472000 | F88: 1163000 | G88: 994000 | H88: 901000
D89: 2034000 | E89: 1465000 | F89: 1157000 | G89: 989000 | H89: 897000
D90: 2024000 | E90: 1458000 | F90: 1151000 | G90: 984000 | H90: 893000
D91: 2014000 | E91: 1451000 | F91: 1145000 | G91: 979000 | H91: 889000
D92: 2004000 | E92: 1444000 | F92: 1139000 | G92: 974000 | H92: 885000
D93: 1994000 | E93: 1437000 | F93: 1133000 | G93: 969000 | H93: 881000
D94: 1984000 | E94: 1430000 | F94: 1127000 | G94: 964000 | H94: 877000
D95: 1974000 | E95: 1423000 | F95: 1121000 | G95: 959000 | H95: 873000
D96: 1964000 | E96: 1416000 | F96: 1115000 | G96: 954000 | H96: 869000
D97: 1954000 | E97: 1409000 | F97: 1109000 | G97: 949000 | H97: 865000
... D112: 1804000 | E112: 1304000 | F112: 1019000 | G112: 874000 | H112: 805000

Sheet  SUPRA GTR EXCLUSIVE  
A1: SUPRA GTR EXCLUSIVE | B1: DP | C1: % DP | D1: JANGKA WAKTU
D2: 12 | E2: 18 | F2: 24 | G2: 30 | H2: 36 | O2: =(I3-I4)*1.5 -> 0
A3: =OTR!E8 -> 29225000 | B3: 3000000 | C3: =B3/$A$3 -> 0.10265184 | D3: 2908000 | E3: 2124000 | F3: 1680000 | G3: 1376000 | H3: 1248000
B4: 3100000 | C4: =B4/$A$3 -> 0.10607357 | D4: 2898000 | E4: 2116000 | F4: 1674000 | G4: 1372000 | H4: 1244000
B5: 3200000 | C5: =B5/$A$3 -> 0.1094953 | D5: 2888000 | E5: 2108000 | F5: 1668000 | G5: 1368000 | H5: 1240000
B6: 3300000 | C6: =B6/$A$3 -> 0.11291702 | D6: 2878000 | E6: 2100000 | F6: 1662000 | G6: 1364000 | H6: 1236000
B7: 3400000 | C7: =B7/$A$3 -> 0.11633875 | D7: 2868000 | E7: 2092000 | F7: 1656000 | G7: 1360000 | H7: 1232000
B8: 3500000 | C8: =B8/$A$3 -> 0.11976048 | D8: 2858000 | E8: 2084000 | F8: 1650000 | G8: 1356000 | H8: 1228000
B9: 3600000 | C9: =B9/$A$3 -> 0.12318221 | D9: 2848000 | E9: 2076000 | F9: 1644000 | G9: 1352000 | H9: 1224000
B10: 3700000 | C10: =B10/$A$3 -> 0.12660393 | D10: 2838000 | E10: 2068000 | F10: 1638000 | G10: 1348000 | H10: 1220000
B11: 3800000 | C11: =B11/$A$3 -> 0.13002566 | D11: 2828000 | E11: 2060000 | F11: 1632000 | G11: 1344000 | H11: 1216000
B12: 3900000 | C12: =B12/$A$3 -> 0.13344739 | D12: 2818000 | E12: 2052000 | F12: 1626000 | G12: 1340000 | H12: 1212000
B13: 4000000 | C13: =B13/$A$3 -> 0.13686912 | D13: 2808000 | E13: 2044000 | F13: 1620000 | G13: 1336000 | H13: 1208000
B14: 4100000 | C14: =B14/$A$3 -> 0.14029085 | D14: 2798000 | E14: 2036000 | F14: 1614000 | G14: 1332000 | H14: 1204000
B15: 4200000 | C15: =B15/$A$3 -> 0.14371257 | D15: 2788000 | E15: 2028000 | F15: 1608000 | G15: 1328000 | H15: 1200000
... B85: 11200000 | C85: =B85/$A$3 -> 0.38323353 | D85: 2088000 | E85: 1468000 | F85: 1188000 | G85: 1048000 | H85: 920000
D86: 2078000 | E86: 1460000 | F86: 1182000 | G86: 1044000 | H86: 916000
D87: 2068000 | E87: 1452000 | F87: 1176000 | G87: 1040000 | H87: 912000
D88: 2058000 | E88: 1444000 | F88: 1170000 | G88: 1036000 | H88: 908000
D89: 2048000 | E89: 1436000 | F89: 1164000 | G89: 1032000 | H89: 904000
D90: 2038000 | E90: 1428000 | F90: 1158000 | G90: 1028000 | H90: 900000
D91: 2028000 | E91: 1420000 | F91: 1152000 | G91: 1024000 | H91: 896000
D92: 2018000 | E92: 1412000 | F92: 1146000 | G92: 1020000 | H92: 892000
D93: 2008000 | E93: 1404000 | F93: 1140000 | G93: 1016000 | H93: 888000
D94: 1998000 | E94: 1396000 | F94: 1134000 | G94: 1012000 | H94: 884000
D95: 1988000 | E95: 1388000 | F95: 1128000 | G95: 1008000 | H95: 880000
D96: 1978000 | E96: 1380000 | F96: 1122000 | G96: 1004000 | H96: 876000
D97: 1968000 | E97: 1372000 | F97: 1116000 | G97: 1000000 | H97: 872000
... D112: 1818000 | E112: 1252000 | F112: 1026000 | G112: 940000 | H112: 812000

Sheet BEAT SPORTY CBS 
A1: BEAT SPORTY CBS | B1: DP | C1: % DP | D1: JANGKA WAKTU
D2: 12 | E2: 18 | F2: 24 | G2: 30 | H2: 36 | I2: .
A3: =OTR!E42 -> 0 | B3: 1500000 | C3: =B3/$A$3 -> #DIV/0! | D3: 1984000 | E3: 1433000 | F3: 1124000 | G3: 956000 | H3: 862000
B4: 1600000 | C4: =B4/$A$3 -> #DIV/0! | D4: 1974000 | E4: 1426000 | F4: 1119000 | G4: 952000 | H4: 858000
B5: 1700000 | C5: =B5/$A$3 -> #DIV/0! | D5: 1964000 | E5: 1419000 | F5: 1114000 | G5: 948000 | H5: 854000
B6: 1800000 | C6: =B6/$A$3 -> #DIV/0! | D6: 1954000 | E6: 1412000 | F6: 1109000 | G6: 944000 | H6: 850000
B7: 1900000 | C7: =B7/$A$3 -> #DIV/0! | D7: 1944000 | E7: 1405000 | F7: 1104000 | G7: 940000 | H7: 846000
B8: 2000000 | C8: =B8/$A$3 -> #DIV/0! | D8: 1934000 | E8: 1398000 | F8: 1099000 | G8: 936000 | H8: 842000
B9: 2100000 | C9: =B9/$A$3 -> #DIV/0! | D9: 1924000 | E9: 1391000 | F9: 1094000 | G9: 932000 | H9: 838000
B10: 2200000 | C10: =B10/$A$3 -> #DIV/0! | D10: 1914000 | E10: 1384000 | F10: 1089000 | G10: 928000 | H10: 834000
B11: 2300000 | C11: =B11/$A$3 -> #DIV/0! | D11: 1904000 | E11: 1377000 | F11: 1084000 | G11: 924000 | H11: 830000
B12: 2400000 | C12: =B12/$A$3 -> #DIV/0! | D12: 1894000 | E12: 1370000 | F12: 1079000 | G12: 920000 | H12: 826000
B13: 2500000 | C13: =B13/$A$3 -> #DIV/0! | D13: 1884000 | E13: 1363000 | F13: 1074000 | G13: 916000 | H13: 822000
B14: 2600000 | C14: =B14/$A$3 -> #DIV/0! | D14: 1874000 | E14: 1356000 | F14: 1069000 | G14: 912000 | H14: 818000
B15: 2700000 | C15: =B15/$A$3 -> #DIV/0! | D15: 1864000 | E15: 1349000 | F15: 1063000 | G15: 907000 | H15: 813000
... B76: 8800000 | C76: =B76/$A$3 -> #DIV/0! | D76: 1244000 | E76: 913000 | F76: 718000 | G76: 617000 | H76: 559000
D77: 1234000 | E77: 906000 | F77: 712000 | G77: 612000 | H77: 555000
D78: 1224000 | E78: 899000 | F78: 707000 | G78: 608000 | H78: 551000
D79: 1214000 | E79: 892000 | F79: 701000 | G79: 603000 | H79: 546000

Sheet BEAT SPORTY CBS ISS 
A1: BEAT SPORTY CBS ISS | B1: DP | C1: % DP | D1: JANGKA WAKTU
D2: 12 | E2: 18 | F2: 24 | G2: 30 | H2: 36
A3: =OTR!E43 -> 0 | B3: 1500000 | C3: =B3/$A$3 -> #DIV/0! | D3: 2054000 | E3: 1488000 | F3: 1164000 | G3: 988000 | H3: 893000
B4: 1600000 | C4: =B4/$A$3 -> #DIV/0! | D4: 2044000 | E4: 1481000 | F4: 1159000 | G4: 984000 | H4: 889000
B5: 1700000 | C5: =B5/$A$3 -> #DIV/0! | D5: 2034000 | E5: 1474000 | F5: 1154000 | G5: 980000 | H5: 885000
B6: 1800000 | C6: =B6/$A$3 -> #DIV/0! | D6: 2024000 | E6: 1467000 | F6: 1149000 | G6: 976000 | H6: 881000
B7: 1900000 | C7: =B7/$A$3 -> #DIV/0! | D7: 2014000 | E7: 1460000 | F7: 1144000 | G7: 972000 | H7: 877000
B8: 2000000 | C8: =B8/$A$3 -> #DIV/0! | D8: 2004000 | E8: 1453000 | F8: 1139000 | G8: 968000 | H8: 873000
B9: 2100000 | C9: =B9/$A$3 -> #DIV/0! | D9: 1994000 | E9: 1446000 | F9: 1134000 | G9: 964000 | H9: 869000
B10: 2200000 | C10: =B10/$A$3 -> #DIV/0! | D10: 1984000 | E10: 1439000 | F10: 1129000 | G10: 960000 | H10: 865000
B11: 2300000 | C11: =B11/$A$3 -> #DIV/0! | D11: 1974000 | E11: 1432000 | F11: 1124000 | G11: 956000 | H11: 861000
B12: 2400000 | C12: =B12/$A$3 -> #DIV/0! | D12: 1964000 | E12: 1425000 | F12: 1119000 | G12: 952000 | H12: 857000
B13: 2500000 | C13: =B13/$A$3 -> #DIV/0! | D13: 1954000 | E13: 1418000 | F13: 1114000 | G13: 948000 | H13: 853000
B14: 2600000 | C14: =B14/$A$3 -> #DIV/0! | D14: 1944000 | E14: 1411000 | F14: 1109000 | G14: 944000 | H14: 849000
B15: 2700000 | C15: =B15/$A$3 -> #DIV/0! | D15: 1934000 | E15: 1404000 | F15: 1104000 | G15: 940000 | H15: 845000
... B78: 9000000 | C78: =B78/$A$3 -> #DIV/0! | D78: 1294000 | E78: 953000 | F78: 747000 | G78: 640000 | H78: 582000
D79: 1284000 | E79: 946000 | F79: 741000 | G79: 636000 | H79: 578000
D80: 1274000 | E80: 939000 | F80: 736000 | G80: 631000 | H80: 574000
D81: 1264000 | E81: 932000 | F81: 730000 | G81: 626000 | H81: 570000

Sheet BEAT SPORTY DX CBS ISS 
A1: BEAT SPORTY DX CBS ISS | B1: DP | C1: % DP | D1: JANGKA WAKTU
D2: 12 | E2: 18 | F2: 24 | G2: 30 | H2: 36
A3: =OTR!E44 -> 0 | B3: 1500000 | C3: =B3/$A$3 -> #DIV/0! | D3: 2066000 | E3: 1490000 | F3: 1168000 | G3: 992000 | H3: 899000
B4: 1600000 | C4: =B4/$A$3 -> #DIV/0! | D4: 2056000 | E4: 1483000 | F4: 1163000 | G4: 988000 | H4: 895000
B5: 1700000 | C5: =B5/$A$3 -> #DIV/0! | D5: 2046000 | E5: 1476000 | F5: 1158000 | G5: 984000 | H5: 891000
B6: 1800000 | C6: =B6/$A$3 -> #DIV/0! | D6: 2036000 | E6: 1469000 | F6: 1153000 | G6: 980000 | H6: 887000
B7: 1900000 | C7: =B7/$A$3 -> #DIV/0! | D7: 2026000 | E7: 1462000 | F7: 1148000 | G7: 976000 | H7: 883000
B8: 2000000 | C8: =B8/$A$3 -> #DIV/0! | D8: 2016000 | E8: 1455000 | F8: 1143000 | G8: 972000 | H8: 879000
B9: 2100000 | C9: =B9/$A$3 -> #DIV/0! | D9: 2006000 | E9: 1448000 | F9: 1138000 | G9: 968000 | H9: 875000
B10: 2200000 | C10: =B10/$A$3 -> #DIV/0! | D10: 1996000 | E10: 1441000 | F10: 1133000 | G10: 964000 | H10: 871000
B11: 2300000 | C11: =B11/$A$3 -> #DIV/0! | D11: 1986000 | E11: 1434000 | F11: 1128000 | G11: 960000 | H11: 867000
B12: 2400000 | C12: =B12/$A$3 -> #DIV/0! | D12: 1976000 | E12: 1427000 | F12: 1123000 | G12: 956000 | H12: 863000
B13: 2500000 | C13: =B13/$A$3 -> #DIV/0! | D13: 1966000 | E13: 1420000 | F13: 1118000 | G13: 952000 | H13: 859000
B14: 2600000 | C14: =B14/$A$3 -> #DIV/0! | D14: 1956000 | E14: 1413000 | F14: 1113000 | G14: 948000 | H14: 855000
B15: 2700000 | C15: =B15/$A$3 -> #DIV/0! | D15: 1946000 | E15: 1406000 | F15: 1108000 | G15: 944000 | H15: 851000
... B60: 7200000 | C60: =B60/$A$3 -> #DIV/0! | D60: 1487000 | E60: 1082000 | F60: 851000 | G60: 728000 | H60: 662000
B61: 7300000 | D61: 1477000 | E61: 1075000 | F61: 846000 | G61: 724000 | H61: 658000
B62: 7400000 | D62: 1467000 | E62: 1068000 | F62: 840000 | G62: 719000 | H62: 653000
B63: 7500000 | D63: 1457000 | E63: 1061000 | F63: 834000 | G63: 714000 | H63: 649000
B64: 7600000 | D64: 1447000 | E64: 1054000 | F64: 829000 | G64: 710000 | H64: 645000
B65: 7700000 | D65: 1437000 | E65: 1047000 | F65: 823000 | G65: 705000 | H65: 641000
B66: 7800000 | D66: 1427000 | E66: 1040000 | F66: 818000 | G66: 700000 | H66: 637000
B67: 7900000 | D67: 1417000 | E67: 1033000 | F67: 812000 | G67: 696000 | H67: 633000
B68: 8000000 | D68: 1407000 | E68: 1026000 | F68: 807000 | G68: 691000 | H68: 629000
B69: 8100000 | D69: 1397000 | E69: 1019000 | F69: 801000 | G69: 686000 | H69: 625000
B70: 8200000 | D70: 1387000 | E70: 1012000 | F70: 795000 | G70: 682000 | H70: 621000
B71: 8300000 | D71: 1377000 | E71: 1005000 | F71: 790000 | G71: 677000 | H71: 616000
B72: 8400000 | D72: 1367000 | E72: 998000 | F72: 784000 | G72: 672000 | H72: 612000
... B76: 8800000 | D76: 1327000 | E76: 969000 | F76: 762000 | G76: 654000 | H76: 596000
D77: 1317000 | E77: 962000 | F77: 757000 | G77: 649000 | H77: 592000
D78: 1307000 | E78: 955000 | F78: 751000 | G78: 644000 | H78: 588000
D79: 1297000 | E79: 948000 | F79: 745000 | G79: 640000 | H79: 584000
D80: 1287000 | E80: 941000 | F80: 740000 | G80: 635000 | H80: 579000
D81: 1277000 | E81: 934000 | F81: 734000 | G81: 630000 | H81: 575000
D82: 1267000 | E82: 927000 | F82: 729000 | G82: 626000 | H82: 571000

Sheet BEAT STREET 
A1: BEAT STREET | B1: DP | C1: % DP | D1: JANGKA WAKTU
D2: 12 | E2: 18 | F2: 24 | G2: 30 | H2: 36
A3: =OTR!E45 -> 0 | B3: 1500000 | C3: =B3/$A$3 -> #DIV/0! | D3: 2053000 | E3: 1482000 | F3: 1163000 | G3: 988000 | H3: 890000
B4: 1600000 | C4: =B4/$A$3 -> #DIV/0! | D4: 2043000 | E4: 1475000 | F4: 1158000 | G4: 984000 | H4: 886000
B5: 1700000 | C5: =B5/$A$3 -> #DIV/0! | D5: 2033000 | E5: 1468000 | F5: 1153000 | G5: 980000 | H5: 882000
B6: 1800000 | C6: =B6/$A$3 -> #DIV/0! | D6: 2023000 | E6: 1461000 | F6: 1148000 | G6: 976000 | H6: 878000
B7: 1900000 | C7: =B7/$A$3 -> #DIV/0! | D7: 2013000 | E7: 1454000 | F7: 1143000 | G7: 972000 | H7: 874000
B8: 2000000 | C8: =B8/$A$3 -> #DIV/0! | D8: 2003000 | E8: 1447000 | F8: 1138000 | G8: 968000 | H8: 870000
B9: 2100000 | C9: =B9/$A$3 -> #DIV/0! | D9: 1993000 | E9: 1440000 | F9: 1133000 | G9: 964000 | H9: 866000
B10: 2200000 | C10: =B10/$A$3 -> #DIV/0! | D10: 1983000 | E10: 1433000 | F10: 1128000 | G10: 960000 | H10: 862000
B11: 2300000 | C11: =B11/$A$3 -> #DIV/0! | D11: 1973000 | E11: 1426000 | F11: 1123000 | G11: 956000 | H11: 858000
B12: 2400000 | C12: =B12/$A$3 -> #DIV/0! | D12: 1963000 | E12: 1419000 | F12: 1118000 | G12: 952000 | H12: 854000
B13: 2500000 | C13: =B13/$A$3 -> #DIV/0! | D13: 1953000 | E13: 1412000 | F13: 1113000 | G13: 948000 | H13: 850000
B14: 2600000 | C14: =B14/$A$3 -> #DIV/0! | D14: 1943000 | E14: 1405000 | F14: 1108000 | G14: 944000 | H14: 846000
B15: 2700000 | C15: =B15/$A$3 -> #DIV/0! | D15: 1933000 | E15: 1398000 | F15: 1102000 | G15: 939000 | H15: 841000
... B60: 7200000 | C60: =B60/$A$3 -> #DIV/0! | D60: 1474000 | E60: 1074000 | F60: 846000 | G60: 724000 | H60: 653000
B61: 7300000 | D61: 1464000 | E61: 1067000 | F61: 840000 | G61: 719000 | H61: 648000
B62: 7400000 | D62: 1454000 | E62: 1060000 | F62: 834000 | G62: 714000 | H62: 644000
B63: 7500000 | D63: 1444000 | E63: 1053000 | F63: 829000 | G63: 710000 | H63: 640000
B64: 7600000 | D64: 1434000 | E64: 1046000 | F64: 823000 | G64: 705000 | H64: 636000
B65: 7700000 | D65: 1424000 | E65: 1039000 | F65: 818000 | G65: 700000 | H65: 632000
B66: 7800000 | D66: 1414000 | E66: 1032000 | F66: 812000 | G66: 696000 | H66: 628000
B67: 7900000 | D67: 1404000 | E67: 1025000 | F67: 807000 | G67: 691000 | H67: 624000
B68: 8000000 | D68: 1394000 | E68: 1018000 | F68: 801000 | G68: 686000 | H68: 620000
B69: 8100000 | D69: 1384000 | E69: 1011000 | F69: 795000 | G69: 682000 | H69: 616000
B70: 8200000 | D70: 1374000 | E70: 1004000 | F70: 790000 | G70: 677000 | H70: 611000
B71: 8300000 | D71: 1364000 | E71: 997000 | F71: 784000 | G71: 672000 | H71: 607000
B72: 8400000 | D72: 1354000 | E72: 990000 | F72: 779000 | G72: 668000 | H72: 603000
... B76: 8800000 | D76: 1314000 | E76: 961000 | F76: 757000 | G76: 649000 | H76: 587000
D77: 1304000 | E77: 954000 | F77: 751000 | G77: 644000 | H77: 583000
D78: 1294000 | E78: 947000 | F78: 745000 | G78: 640000 | H78: 579000
D79: 1284000 | E79: 940000 | F79: 740000 | G79: 635000 | H79: 574000
D80: 1274000 | E80: 933000 | F80: 734000 | G80: 630000 | H80: 570000
D81: 1264000 | E81: 926000 | F81: 729000 | G81: 626000 | H81: 566000

Sheet OLD BEAT CBS
A1: BEAT SPORTY CBS | B1: DP | C1: % DP | D1: JANGKA WAKTU
D2: 12 | E2: 18 | F2: 24 | G2: 30 | H2: 36
A3: =OTR!E89 -> 0 | B3: 1500000 | C3: =B3/$A$3 -> #DIV/0! | D3: 2094000 | E3: 1512000 | F3: 1181000 | G3: 1000000 | H3: 906000
B4: 1600000 | C4: =B4/$A$3 -> #DIV/0! | D4: 2084000 | E4: 1505000 | F4: 1176000 | G4: 996000 | H4: 902000
B5: 1700000 | C5: =B5/$A$3 -> #DIV/0! | D5: 2074000 | E5: 1498000 | F5: 1171000 | G5: 992000 | H5: 898000
B6: 1800000 | C6: =B6/$A$3 -> #DIV/0! | D6: 2064000 | E6: 1491000 | F6: 1166000 | G6: 988000 | H6: 894000
B7: 1900000 | C7: =B7/$A$3 -> #DIV/0! | D7: 2054000 | E7: 1484000 | F7: 1161000 | G7: 984000 | H7: 890000
B8: 2000000 | C8: =B8/$A$3 -> #DIV/0! | D8: 2044000 | E8: 1477000 | F8: 1156000 | G8: 980000 | H8: 886000
B9: 2100000 | C9: =B9/$A$3 -> #DIV/0! | D9: 2034000 | E9: 1470000 | F9: 1151000 | G9: 976000 | H9: 882000
B10: 2200000 | C10: =B10/$A$3 -> #DIV/0! | D10: 2024000 | E10: 1463000 | F10: 1146000 | G10: 972000 | H10: 878000
B11: 2300000 | C11: =B11/$A$3 -> #DIV/0! | D11: 2014000 | E11: 1456000 | F11: 1141000 | G11: 968000 | H11: 874000
B12: 2400000 | C12: =B12/$A$3 -> #DIV/0! | D12: 2004000 | E12: 1449000 | F12: 1136000 | G12: 964000 | H12: 870000
B13: 2500000 | C13: =B13/$A$3 -> #DIV/0! | D13: 1994000 | E13: 1442000 | F13: 1131000 | G13: 960000 | H13: 866000
B14: 2600000 | C14: =B14/$A$3 -> #DIV/0! | D14: 1984000 | E14: 1435000 | F14: 1126000 | G14: 956000 | H14: 862000
B15: 2700000 | C15: =B15/$A$3 -> #DIV/0! | D15: 1974000 | E15: 1428000 | F15: 1121000 | G15: 952000 | H15: 858000
... B76: 8800000 | C76: =B76/$A$3 -> #DIV/0! | D76: 1364000 | E76: 1001000 | F76: 816000 | G76: 708000 | H76: 614000
D77: 1354000 | E77: 994000 | F77: 811000 | G77: 704000 | H77: 610000
D78: 1344000 | E78: 987000 | F78: 806000 | G78: 700000 | H78: 606000
D79: 1334000 | E79: 980000 | F79: 801000 | G79: 696000 | H79: 602000
D80: 1324000 | E80: 973000 | F80: 796000 | G80: 692000 | H80: 598000
D81: 1314000 | E81: 966000 | F81: 791000 | G81: 688000 | H81: 594000
D82: 1304000 | E82: 959000 | F82: 786000 | G82: 684000 | H82: 590000
D83: 1294000 | E83: 952000 | F83: 781000 | G83: 680000 | H83: 586000
D84: 1284000 | E84: 945000 | F84: 776000 | G84: 676000 | H84: 582000
D85: 1274000 | E85: 938000 | F85: 771000 | G85: 672000 | H85: 578000
D86: 1264000 | E86: 931000 | F86: 766000 | G86: 668000 | H86: 574000

Sheet NEW BEAT ISS
A1: NEW BEAT SPORTY CBS ISS | B1: DP | C1: % DP | D1: JANGKA WAKTU
D2: 12 | E2: 18 | F2: 24 | G2: 30 | H2: 36
A3: =OTR!E90 -> 0 | B3: 1500000 | C3: =B3/$A$3 -> #DIV/0! | D3: 2124000 | E3: 1537000 | F3: 1199000 | G3: 1016000 | H3: 921000
B4: 1600000 | C4: =B4/$A$3 -> #DIV/0! | D4: 2114000 | E4: 1530000 | F4: 1194000 | G4: 1012000 | H4: 917000
B5: 1700000 | C5: =B5/$A$3 -> #DIV/0! | D5: 2104000 | E5: 1523000 | F5: 1189000 | G5: 1008000 | H5: 913000
B6: 1800000 | C6: =B6/$A$3 -> #DIV/0! | D6: 2094000 | E6: 1516000 | F6: 1184000 | G6: 1004000 | H6: 909000
B7: 1900000 | C7: =B7/$A$3 -> #DIV/0! | D7: 2084000 | E7: 1509000 | F7: 1179000 | G7: 1000000 | H7: 905000
B8: 2000000 | C8: =B8/$A$3 -> #DIV/0! | D8: 2074000 | E8: 1502000 | F8: 1174000 | G8: 996000 | H8: 901000
B9: 2100000 | C9: =B9/$A$3 -> #DIV/0! | D9: 2064000 | E9: 1495000 | F9: 1169000 | G9: 992000 | H9: 897000
B10: 2200000 | C10: =B10/$A$3 -> #DIV/0! | D10: 2054000 | E10: 1488000 | F10: 1164000 | G10: 988000 | H10: 893000
B11: 2300000 | C11: =B11/$A$3 -> #DIV/0! | D11: 2044000 | E11: 1481000 | F11: 1159000 | G11: 984000 | H11: 889000
B12: 2400000 | C12: =B12/$A$3 -> #DIV/0! | D12: 2034000 | E12: 1474000 | F12: 1154000 | G12: 980000 | H12: 885000
B13: 2500000 | C13: =B13/$A$3 -> #DIV/0! | D13: 2024000 | E13: 1467000 | F13: 1149000 | G13: 976000 | H13: 881000
B14: 2600000 | C14: =B14/$A$3 -> #DIV/0! | D14: 2014000 | E14: 1460000 | F14: 1144000 | G14: 972000 | H14: 877000
B15: 2700000 | C15: =B15/$A$3 -> #DIV/0! | D15: 2004000 | E15: 1453000 | F15: 1139000 | G15: 968000 | H15: 873000
... B78: 9000000 | C78: =B78/$A$3 -> #DIV/0! | D78: 1364000 | E78: 1002000 | F78: 786000 | G78: 673000 | H78: 611000
D79: 1354000 | E79: 995000 | F79: 780000 | G79: 668000 | H79: 607000
D80: 1344000 | E80: 988000 | F80: 775000 | G80: 664000 | H80: 602000
D81: 1334000 | E81: 981000 | F81: 769000 | G81: 659000 | H81: 598000
D82: 1324000 | E82: 974000 | F82: 764000 | G82: 654000 | H82: 594000
D83: 1314000 | E83: 967000 | F83: 758000 | G83: 650000 | H83: 590000
D84: 1304000 | E84: 960000 | F84: 752000 | G84: 645000 | H84: 586000
D85: 1294000 | E85: 953000 | F85: 747000 | G85: 640000 | H85: 582000
D86: 1284000 | E86: 946000 | F86: 741000 | G86: 636000 | H86: 578000
D87: 1274000 | E87: 939000 | F87: 736000 | G87: 631000 | H87: 574000
D88: 1264000 | E88: 932000 | F88: 730000 | G88: 626000 | H88: 570000

Sheet OLD BEAT ISS DX
A1: BEAT SPORTY DX CBS ISS | B1: DP | C1: % DP | D1: JANGKA WAKTU
D2: 12 | E2: 18 | F2: 24 | G2: 30 | H2: 36
A3: =OTR!E91 -> 0 | B3: 1500000 | C3: =B3/$A$3 -> #DIV/0! | D3: 2176000 | E3: 1569000 | F3: 1225000 | G3: 1036000 | H3: 943000
B4: 1600000 | C4: =B4/$A$3 -> #DIV/0! | D4: 2166000 | E4: 1562000 | F4: 1220000 | G4: 1032000 | H4: 939000
B5: 1700000 | C5: =B5/$A$3 -> #DIV/0! | D5: 2156000 | E5: 1555000 | F5: 1215000 | G5: 1028000 | H5: 935000
B6: 1800000 | C6: =B6/$A$3 -> #DIV/0! | D6: 2146000 | E6: 1548000 | F6: 1210000 | G6: 1024000 | H6: 931000
B7: 1900000 | C7: =B7/$A$3 -> #DIV/0! | D7: 2136000 | E7: 1541000 | F7: 1205000 | G7: 1020000 | H7: 927000
B8: 2000000 | C8: =B8/$A$3 -> #DIV/0! | D8: 2126000 | E8: 1534000 | F8: 1200000 | G8: 1016000 | H8: 923000
B9: 2100000 | C9: =B9/$A$3 -> #DIV/0! | D9: 2116000 | E9: 1527000 | F9: 1195000 | G9: 1012000 | H9: 919000
B10: 2200000 | C10: =B10/$A$3 -> #DIV/0! | D10: 2106000 | E10: 1520000 | F10: 1190000 | G10: 1008000 | H10: 915000
B11: 2300000 | C11: =B11/$A$3 -> #DIV/0! | D11: 2096000 | E11: 1513000 | F11: 1185000 | G11: 1004000 | H11: 911000
B12: 2400000 | C12: =B12/$A$3 -> #DIV/0! | D12: 2086000 | E12: 1506000 | F12: 1180000 | G12: 1000000 | H12: 907000
B13: 2500000 | C13: =B13/$A$3 -> #DIV/0! | D13: 2076000 | E13: 1499000 | F13: 1175000 | G13: 996000 | H13: 903000
B14: 2600000 | C14: =B14/$A$3 -> #DIV/0! | D14: 2066000 | E14: 1492000 | F14: 1170000 | G14: 992000 | H14: 899000
B15: 2700000 | C15: =B15/$A$3 -> #DIV/0! | D15: 2056000 | E15: 1485000 | F15: 1165000 | G15: 988000 | H15: 895000
... B86: 9800000 | C86: =B86/$A$3 -> #DIV/0! | D86: 1346000 | E86: 988000 | F86: 810000 | G86: 704000 | H86: 611000
D87: 1336000 | E87: 981000 | F87: 805000 | G87: 700000 | H87: 607000
D88: 1326000 | E88: 974000 | F88: 800000 | G88: 696000 | H88: 603000
D89: 1316000 | E89: 967000 | F89: 795000 | G89: 692000 | H89: 599000

Sheet OLD BEAT STREET
A1: BEAT STREET | B1: DP | C1: % DP | D1: JANGKA WAKTU
D2: 12 | E2: 18 | F2: 24 | G2: 30 | H2: 36
A3: =OTR!E92 -> 0 | B3: 1500000 | C3: =B3/$A$3 -> #DIV/0! | D3: 2163000 | E3: 1561000 | F3: 1220000 | G3: 1032000 | H3: 934000
B4: 1600000 | C4: =B4/$A$3 -> #DIV/0! | D4: 2153000 | E4: 1554000 | F4: 1215000 | G4: 1028000 | H4: 930000
B5: 1700000 | C5: =B5/$A$3 -> #DIV/0! | D5: 2143000 | E5: 1547000 | F5: 1210000 | G5: 1024000 | H5: 926000
B6: 1800000 | C6: =B6/$A$3 -> #DIV/0! | D6: 2133000 | E6: 1540000 | F6: 1205000 | G6: 1020000 | H6: 922000
B7: 1900000 | C7: =B7/$A$3 -> #DIV/0! | D7: 2123000 | E7: 1533000 | F7: 1200000 | G7: 1016000 | H7: 918000
B8: 2000000 | C8: =B8/$A$3 -> #DIV/0! | D8: 2113000 | E8: 1526000 | F8: 1195000 | G8: 1012000 | H8: 914000
B9: 2100000 | C9: =B9/$A$3 -> #DIV/0! | D9: 2103000 | E9: 1519000 | F9: 1190000 | G9: 1008000 | H9: 910000
B10: 2200000 | C10: =B10/$A$3 -> #DIV/0! | D10: 2093000 | E10: 1512000 | F10: 1185000 | G10: 1004000 | H10: 906000
B11: 2300000 | C11: =B11/$A$3 -> #DIV/0! | D11: 2083000 | E11: 1505000 | F11: 1180000 | G11: 1000000 | H11: 902000
B12: 2400000 | C12: =B12/$A$3 -> #DIV/0! | D12: 2073000 | E12: 1498000 | F12: 1175000 | G12: 996000 | H12: 898000
B13: 2500000 | C13: =B13/$A$3 -> #DIV/0! | D13: 2063000 | E13: 1491000 | F13: 1170000 | G13: 992000 | H13: 894000
B14: 2600000 | C14: =B14/$A$3 -> #DIV/0! | D14: 2053000 | E14: 1484000 | F14: 1165000 | G14: 988000 | H14: 890000
B15: 2700000 | C15: =B15/$A$3 -> #DIV/0! | D15: 2043000 | E15: 1477000 | F15: 1160000 | G15: 984000 | H15: 886000
... B85: 9700000 | C85: =B85/$A$3 -> #DIV/0! | D85: 1343000 | E85: 987000 | F85: 810000 | G85: 704000 | H85: 606000
D86: 1333000 | E86: 980000 | F86: 805000 | G86: 700000 | H86: 602000
D87: 1323000 | E87: 973000 | F87: 800000 | G87: 696000 | H87: 598000
D88: 1313000 | E88: 966000 | F88: 795000 | G88: 692000 | H88: 594000

Sheet NEW BEAT CBS
A1: NEW BEAT SPORTY CBS | B1: DP | C1: % DP | D1: JANGKA WAKTU
D2: 12 | E2: 18 | F2: 24 | G2: 30 | H2: 36 | I2: 42
A3: =OTR!E101 -> 21250000 | B3: 2200000 | C3: =B3/$A$3 -> 0.10352941 | D3: 2259000 | E3: 1628000 | F3: 1264000 | G3: 1066000 | H3: 972000 | I3: 922000
B4: 2300000 | C4: =B4/$A$3 -> 0.10823529 | D4: 2249000 | E4: 1621000 | F4: 1259000 | G4: 1062000 | H4: 968000 | I4: 918000
B5: 2400000 | C5: =B5/$A$3 -> 0.11294118 | D5: 2239000 | E5: 1614000 | F5: 1254000 | G5: 1058000 | H5: 964000 | I5: 914000
B6: 2500000 | C6: =B6/$A$3 -> 0.11764706 | D6: 2229000 | E6: 1607000 | F6: 1249000 | G6: 1054000 | H6: 960000 | I6: 910000
B7: 2600000 | C7: =B7/$A$3 -> 0.12235294 | D7: 2219000 | E7: 1600000 | F7: 1244000 | G7: 1050000 | H7: 956000 | I7: 906000
B8: 2700000 | C8: =B8/$A$3 -> 0.12705882 | D8: 2209000 | E8: 1593000 | F8: 1239000 | G8: 1046000 | H8: 952000 | I8: 902000
B9: 2800000 | C9: =B9/$A$3 -> 0.13176471 | D9: 2199000 | E9: 1586000 | F9: 1234000 | G9: 1042000 | H9: 948000 | I9: 898000
B10: 2900000 | C10: =B10/$A$3 -> 0.13647059 | D10: 2189000 | E10: 1579000 | F10: 1229000 | G10: 1038000 | H10: 944000 | I10: 894000
B11: 3000000 | C11: =B11/$A$3 -> 0.14117647 | D11: 2179000 | E11: 1572000 | F11: 1224000 | G11: 1034000 | H11: 940000 | I11: 890000
B12: 3100000 | C12: =B12/$A$3 -> 0.14588235 | D12: 2169000 | E12: 1565000 | F12: 1219000 | G12: 1030000 | H12: 936000 | I12: 886000
B13: 3200000 | C13: =B13/$A$3 -> 0.15058824 | D13: 2159000 | E13: 1558000 | F13: 1214000 | G13: 1026000 | H13: 932000 | I13: 882000
B14: 3300000 | C14: =B14/$A$3 -> 0.15529412 | D14: 2149000 | E14: 1551000 | F14: 1209000 | G14: 1022000 | H14: 928000 | I14: 878000
B15: 3400000 | C15: =B15/$A$3 -> 0.16 | D15: 2139000 | E15: 1544000 | F15: 1204000 | G15: 1018000 | H15: 924000 | I15: 874000
... B111: 13000000 | C111: =B111/$A$3 -> 0.61176471 | D111: 1179000 | E111: 872000 | F111: 724000 | G111: 634000 | H111: 540000 | I111: 490000
D112: 1169000 | E112: 865000 | F112: 719000 | G112: 630000 | H112: 536000 | I112: 486000
D113: 1159000 | E113: 858000 | F113: 714000 | G113: 626000 | H113: 532000 | I113: 482000
D114: 1149000 | E114: 851000 | F114: 709000 | G114: 622000 | H114: 528000 | I114: 478000
D115: 1139000 | E115: 844000 | F115: 704000 | G115: 618000 | H115: 524000 | I115: 474000
D116: 1129000 | E116: 837000 | F116: 699000 | G116: 614000 | H116: 520000 | I116: 470000

Sheet NEW BEAT DX
A1: NEW BEAT SPORTY DX CBS ISS | B1: DP | C1: % DP | D1: JANGKA WAKTU
D2: 12 | E2: 18 | F2: 24 | G2: 30 | H2: 36 | I2: 42
A3: =OTR!E102 -> 22150000 | B3: 2300000 | C3: =B3/$A$3 -> 0.10383747 | D3: 2331000 | E3: 1678000 | F3: 1303000 | G3: 1098000 | H3: 1005000 | I3: 955000
B4: 2400000 | C4: =B4/$A$3 -> 0.10835214 | D4: 2321000 | E4: 1671000 | F4: 1298000 | G4: 1094000 | H4: 1001000 | I4: 951000
B5: 2500000 | C5: =B5/$A$3 -> 0.11286682 | D5: 2311000 | E5: 1664000 | F5: 1293000 | G5: 1090000 | H5: 997000 | I5: 947000
B6: 2600000 | C6: =B6/$A$3 -> 0.11738149 | D6: 2301000 | E6: 1657000 | F6: 1288000 | G6: 1086000 | H6: 993000 | I6: 943000
B7: 2700000 | C7: =B7/$A$3 -> 0.12189616 | D7: 2291000 | E7: 1650000 | F7: 1283000 | G7: 1082000 | H7: 989000 | I7: 939000
B8: 2800000 | C8: =B8/$A$3 -> 0.12641084 | D8: 2281000 | E8: 1643000 | F8: 1278000 | G8: 1078000 | H8: 985000 | I8: 935000
B9: 2900000 | C9: =B9/$A$3 -> 0.13092551 | D9: 2271000 | E9: 1636000 | F9: 1273000 | G9: 1074000 | H9: 981000 | I9: 931000
B10: 3000000 | C10: =B10/$A$3 -> 0.13544018 | D10: 2261000 | E10: 1629000 | F10: 1268000 | G10: 1070000 | H10: 977000 | I10: 927000
B11: 3100000 | C11: =B11/$A$3 -> 0.13995485 | D11: 2251000 | E11: 1622000 | F11: 1263000 | G11: 1066000 | H11: 973000 | I11: 923000
B12: 3200000 | C12: =B12/$A$3 -> 0.14446953 | D12: 2241000 | E12: 1615000 | F12: 1258000 | G12: 1062000 | H12: 969000 | I12: 919000
B13: 3300000 | C13: =B13/$A$3 -> 0.1489842 | D13: 2231000 | E13: 1608000 | F13: 1253000 | G13: 1058000 | H13: 965000 | I13: 915000
B14: 3400000 | C14: =B14/$A$3 -> 0.15349887 | D14: 2221000 | E14: 1601000 | F14: 1248000 | G14: 1054000 | H14: 961000 | I14: 911000
B15: 3500000 | C15: =B15/$A$3 -> 0.15801354 | D15: 2211000 | E15: 1594000 | F15: 1243000 | G15: 1050000 | H15: 957000 | I15: 907000
... B110: 13000000 | C110: =B110/$A$3 -> 0.58690745 | D110: 1261000 | E110: 929000 | F110: 768000 | G110: 670000 | H110: 577000 | I110: 527000
D111: 1251000 | E111: 922000 | F111: 763000 | G111: 666000 | H111: 573000 | I111: 523000
D112: 1241000 | E112: 915000 | F112: 758000 | G112: 662000 | H112: 569000 | I112: 519000
D113: 1231000 | E113: 908000 | F113: 753000 | G113: 658000 | H113: 565000 | I113: 515000
D114: 1221000 | E114: 901000 | F114: 748000 | G114: 654000 | H114: 561000 | I114: 511000
D115: 1211000 | E115: 894000 | F115: 743000 | G115: 650000 | H115: 557000 | I115: 507000
D116: 1201000 | E116: 887000 | F116: 738000 | G116: 646000 | H116: 553000 | I116: 503000
D117: 1191000 | E117: 880000 | F117: 733000 | G117: 642000 | H117: 549000 | I117: 499000
D118: 1181000 | E118: 873000 | F118: 728000 | G118: 638000 | H118: 545000 | I118: 495000
D119: 1171000 | E119: 866000 | F119: 723000 | G119: 634000 | H119: 541000 | I119: 491000
D120: 1161000 | E120: 859000 | F120: 718000 | G120: 630000 | H120: 537000 | I120: 487000

Sheet NEW BEAT DX SMART KEY
A1: NEW BEAT SPORTY DX CBS ISS SMART KEY | B1: DP | C1: % DP | D1: JANGKA WAKTU
D2: 12 | E2: 18 | F2: 24 | G2: 30 | H2: 36 | I2: 42
A3: =OTR!E103 -> 22700000 | B3: 2300000 | C3: =B3/$A$3 -> 0.10132159 | D3: 2391000 | E3: 1720000 | F3: 1333000 | G3: 1122000 | H3: 1029000 | I3: 979000
B4: 2400000 | C4: =B4/$A$3 -> 0.10572687 | D4: 2381000 | E4: 1713000 | F4: 1328000 | G4: 1118000 | H4: 1025000 | I4: 975000
B5: 2500000 | C5: =B5/$A$3 -> 0.11013216 | D5: 2371000 | E5: 1706000 | F5: 1323000 | G5: 1114000 | H5: 1021000 | I5: 971000
B6: 2600000 | C6: =B6/$A$3 -> 0.11453744 | D6: 2361000 | E6: 1699000 | F6: 1318000 | G6: 1110000 | H6: 1017000 | I6: 967000
B7: 2700000 | C7: =B7/$A$3 -> 0.11894273 | D7: 2351000 | E7: 1692000 | F7: 1313000 | G7: 1106000 | H7: 1013000 | I7: 963000
B8: 2800000 | C8: =B8/$A$3 -> 0.12334802 | D8: 2341000 | E8: 1685000 | F8: 1308000 | G8: 1102000 | H8: 1009000 | I8: 959000
B9: 2900000 | C9: =B9/$A$3 -> 0.1277533 | D9: 2331000 | E9: 1678000 | F9: 1303000 | G9: 1098000 | H9: 1005000 | I9: 955000
B10: 3000000 | C10: =B10/$A$3 -> 0.13215859 | D10: 2321000 | E10: 1671000 | F10: 1298000 | G10: 1094000 | H10: 1001000 | I10: 951000
B11: 3100000 | C11: =B11/$A$3 -> 0.13656388 | D11: 2311000 | E11: 1664000 | F11: 1293000 | G11: 1090000 | H11: 997000 | I11: 947000
B12: 3200000 | C12: =B12/$A$3 -> 0.14096916 | D12: 2301000 | E12: 1657000 | F12: 1288000 | G12: 1086000 | H12: 993000 | I12: 943000
B13: 3300000 | C13: =B13/$A$3 -> 0.14537445 | D13: 2291000 | E13: 1650000 | F13: 1283000 | G13: 1082000 | H13: 989000 | I13: 939000
B14: 3400000 | C14: =B14/$A$3 -> 0.14977974 | D14: 2281000 | E14: 1643000 | F14: 1278000 | G14: 1078000 | H14: 985000 | I14: 935000
B15: 3500000 | C15: =B15/$A$3 -> 0.15418502 | D15: 2271000 | E15: 1636000 | F15: 1273000 | G15: 1074000 | H15: 981000 | I15: 931000
... B113: 13300000 | C113: =B113/$A$3 -> 0.58590308 | D113: 1291000 | E113: 950000 | F113: 783000 | G113: 682000 | H113: 589000 | I113: 539000
D114: 1281000 | E114: 943000 | F114: 778000 | G114: 678000 | H114: 585000 | I114: 535000
D115: 1271000 | E115: 936000 | F115: 773000 | G115: 674000 | H115: 581000 | I115: 531000
D116: 1261000 | E116: 929000 | F116: 768000 | G116: 670000 | H116: 577000 | I116: 527000
D117: 1251000 | E117: 922000 | F117: 763000 | G117: 666000 | H117: 573000 | I117: 523000
D118: 1241000 | E118: 915000 | F118: 758000 | G118: 662000 | H118: 569000 | I118: 519000
D119: 1231000 | E119: 908000 | F119: 753000 | G119: 658000 | H119: 565000 | I119: 515000
D120: 1221000 | E120: 901000 | F120: 748000 | G120: 654000 | H120: 561000 | I120: 511000
D121: 1211000 | E121: 894000 | F121: 743000 | G121: 650000 | H121: 557000 | I121: 507000
D122: 1201000 | E122: 887000 | F122: 738000 | G122: 646000 | H122: 553000 | I122: 503000
D123: 1191000 | E123: 880000 | F123: 733000 | G123: 642000 | H123: 549000 | I123: 499000

Sheet NEW BEAT STREET
A1: NEW BEAT STREET | B1: DP | C1: % DP | D1: JANGKA WAKTU
D2: 12 | E2: 18 | F2: 24 | G2: 30 | H2: 36 | I2: 42
A3: =OTR!E104 -> 22150000 | B3: 2300000 | C3: =B3/$A$3 -> 0.10383747 | D3: 2338000 | E3: 1684000 | F3: 1308000 | G3: 1102000 | H3: 1004000 | I3: 954000
B4: 2400000 | C4: =B4/$A$3 -> 0.10835214 | D4: 2328000 | E4: 1677000 | F4: 1303000 | G4: 1098000 | H4: 1000000 | I4: 950000
B5: 2500000 | C5: =B5/$A$3 -> 0.11286682 | D5: 2318000 | E5: 1670000 | F5: 1298000 | G5: 1094000 | H5: 996000 | I5: 946000
B6: 2600000 | C6: =B6/$A$3 -> 0.11738149 | D6: 2308000 | E6: 1663000 | F6: 1293000 | G6: 1090000 | H6: 992000 | I6: 942000
B7: 2700000 | C7: =B7/$A$3 -> 0.12189616 | D7: 2298000 | E7: 1656000 | F7: 1288000 | G7: 1086000 | H7: 988000 | I7: 938000
B8: 2800000 | C8: =B8/$A$3 -> 0.12641084 | D8: 2288000 | E8: 1649000 | F8: 1283000 | G8: 1082000 | H8: 984000 | I8: 934000
B9: 2900000 | C9: =B9/$A$3 -> 0.13092551 | D9: 2278000 | E9: 1642000 | F9: 1278000 | G9: 1078000 | H9: 980000 | I9: 930000
B10: 3000000 | C10: =B10/$A$3 -> 0.13544018 | D10: 2268000 | E10: 1635000 | F10: 1273000 | G10: 1074000 | H10: 976000 | I10: 926000
B11: 3100000 | C11: =B11/$A$3 -> 0.13995485 | D11: 2258000 | E11: 1628000 | F11: 1268000 | G11: 1070000 | H11: 972000 | I11: 922000
B12: 3200000 | C12: =B12/$A$3 -> 0.14446953 | D12: 2248000 | E12: 1621000 | F12: 1263000 | G12: 1066000 | H12: 968000 | I12: 918000
B13: 3300000 | C13: =B13/$A$3 -> 0.1489842 | D13: 2238000 | E13: 1614000 | F13: 1258000 | G13: 1062000 | H13: 964000 | I13: 914000
B14: 3400000 | C14: =B14/$A$3 -> 0.15349887 | D14: 2228000 | E14: 1607000 | F14: 1253000 | G14: 1058000 | H14: 960000 | I14: 910000
B15: 3500000 | C15: =B15/$A$3 -> 0.15801354 | D15: 2218000 | E15: 1600000 | F15: 1248000 | G15: 1054000 | H15: 956000 | I15: 906000
... B110: 13000000 | C110: =B110/$A$3 -> 0.58690745 | D110: 1268000 | E110: 935000 | F110: 773000 | G110: 674000 | H110: 576000 | I110: 526000
D111: 1258000 | E111: 928000 | F111: 768000 | G111: 670000 | H111: 572000 | I111: 522000
D112: 1248000 | E112: 921000 | F112: 763000 | G112: 666000 | H112: 568000 | I112: 518000
D113: 1238000 | E113: 914000 | F113: 758000 | G113: 662000 | H113: 564000 | I113: 514000
D114: 1228000 | E114: 907000 | F114: 753000 | G114: 658000 | H114: 560000 | I114: 510000
D115: 1218000 | E115: 900000 | F115: 748000 | G115: 654000 | H115: 556000 | I115: 506000
D116: 1208000 | E116: 893000 | F116: 743000 | G116: 650000 | H116: 552000 | I116: 502000
D117: 1198000 | E117: 886000 | F117: 738000 | G117: 646000 | H117: 548000 | I117: 498000
D118: 1188000 | E118: 879000 | F118: 733000 | G118: 642000 | H118: 544000 | I118: 494000
D119: 1178000 | E119: 872000 | F119: 728000 | G119: 638000 | H119: 540000 | I119: 490000
D120: 1168000 | E120: 865000 | F120: 723000 | G120: 634000 | H120: 536000 | I120: 486000

Sheet  GENIO CBS BK   
A1: GENIO CBS BK | B1: DP | C1: % DP | D1: JANGKA WAKTU
D2: 12 | E2: 18 | F2: 24 | G2: 30 | H2: 36
A3: =OTR!E37 -> 22300000 | B3: 2300000 | C3: =B3/$A$3 -> 0.10313901 | D3: 2334000 | E3: 1673000 | F3: 1315000 | G3: 1116000 | H3: 1005000
B4: 2400000 | C4: =B4/$A$3 -> 0.10762332 | D4: 2324000 | E4: 1666000 | F4: 1310000 | G4: 1112000 | H4: 1001000
B5: 2500000 | C5: =B5/$A$3 -> 0.11210762 | D5: 2314000 | E5: 1659000 | F5: 1305000 | G5: 1108000 | H5: 997000
B6: 2600000 | C6: =B6/$A$3 -> 0.11659193 | D6: 2304000 | E6: 1652000 | F6: 1300000 | G6: 1104000 | H6: 993000
B7: 2700000 | C7: =B7/$A$3 -> 0.12107623 | D7: 2294000 | E7: 1645000 | F7: 1295000 | G7: 1100000 | H7: 989000
B8: 2800000 | C8: =B8/$A$3 -> 0.12556054 | D8: 2284000 | E8: 1638000 | F8: 1290000 | G8: 1096000 | H8: 985000
B9: 2900000 | C9: =B9/$A$3 -> 0.13004484 | D9: 2274000 | E9: 1631000 | F9: 1285000 | G9: 1092000 | H9: 981000
B10: 3000000 | C10: =B10/$A$3 -> 0.13452915 | D10: 2264000 | E10: 1624000 | F10: 1280000 | G10: 1088000 | H10: 977000
B11: 3100000 | C11: =B11/$A$3 -> 0.13901345 | D11: 2254000 | E11: 1617000 | F11: 1275000 | G11: 1084000 | H11: 973000
B12: 3200000 | C12: =B12/$A$3 -> 0.14349776 | D12: 2244000 | E12: 1610000 | F12: 1270000 | G12: 1080000 | H12: 969000
B13: 3300000 | C13: =B13/$A$3 -> 0.14798206 | D13: 2234000 | E13: 1603000 | F13: 1265000 | G13: 1076000 | H13: 965000
B14: 3400000 | C14: =B14/$A$3 -> 0.15246637 | D14: 2224000 | E14: 1596000 | F14: 1260000 | G14: 1072000 | H14: 961000
B15: 3500000 | C15: =B15/$A$3 -> 0.15695067 | D15: 2214000 | E15: 1589000 | F15: 1255000 | G15: 1068000 | H15: 957000
... B66: 8600000 | C66: =B66/$A$3 -> 0.38565022 | D66: 1704000 | E66: 1232000 | F66: 1000000 | G66: 864000 | H66: 753000
D67: 1694000 | E67: 1225000 | F67: 995000 | G67: 860000 | H67: 749000
D68: 1684000 | E68: 1218000 | F68: 990000 | G68: 856000 | H68: 745000
D69: 1674000 | E69: 1211000 | F69: 985000 | G69: 852000 | H69: 741000
D70: 1664000 | E70: 1204000 | F70: 980000 | G70: 848000 | H70: 737000
D71: 1654000 | E71: 1197000 | F71: 975000 | G71: 844000 | H71: 733000
D72: 1644000 | E72: 1190000 | F72: 970000 | G72: 840000 | H72: 729000
D73: 1634000 | E73: 1183000 | F73: 965000 | G73: 836000 | H73: 725000
D74: 1624000 | E74: 1176000 | F74: 960000 | G74: 832000 | H74: 721000
D75: 1614000 | E75: 1169000 | F75: 955000 | G75: 828000 | H75: 717000
D76: 1604000 | E76: 1162000 | F76: 950000 | G76: 824000 | H76: 713000
D77: 1594000 | E77: 1155000 | F77: 945000 | G77: 820000 | H77: 709000
D78: 1584000 | E78: 1148000 | F78: 940000 | G78: 816000 | H78: 705000
... D83: 1534000 | E83: 1113000 | F83: 915000 | G83: 796000 | H83: 685000

Sheet GENIO CBS PH & PD
A1: GENIO CBS PH & PD | B1: DP | C1: % DP | D1: JANGKA WAKTU
D2: 12 | E2: 18 | F2: 24 | G2: 30 | H2: 36
A3: =OTR!E38 -> 22500000 | B3: 2300000 | C3: =B3/$A$3 -> 0.10222222 | D3: 2354000 | E3: 1687000 | F3: 1325000 | G3: 1124000 | H3: 1013000
B4: 2400000 | C4: =B4/$A$3 -> 0.10666667 | D4: 2344000 | E4: 1680000 | F4: 1320000 | G4: 1120000 | H4: 1009000
B5: 2500000 | C5: =B5/$A$3 -> 0.11111111 | D5: 2334000 | E5: 1673000 | F5: 1315000 | G5: 1116000 | H5: 1005000
B6: 2600000 | C6: =B6/$A$3 -> 0.11555556 | D6: 2324000 | E6: 1666000 | F6: 1310000 | G6: 1112000 | H6: 1001000
B7: 2700000 | C7: =B7/$A$3 -> 0.12 | D7: 2314000 | E7: 1659000 | F7: 1305000 | G7: 1108000 | H7: 997000
B8: 2800000 | C8: =B8/$A$3 -> 0.12444444 | D8: 2304000 | E8: 1652000 | F8: 1300000 | G8: 1104000 | H8: 993000
B9: 2900000 | C9: =B9/$A$3 -> 0.12888889 | D9: 2294000 | E9: 1645000 | F9: 1295000 | G9: 1100000 | H9: 989000
B10: 3000000 | C10: =B10/$A$3 -> 0.13333333 | D10: 2284000 | E10: 1638000 | F10: 1290000 | G10: 1096000 | H10: 985000
B11: 3100000 | C11: =B11/$A$3 -> 0.13777778 | D11: 2274000 | E11: 1631000 | F11: 1285000 | G11: 1092000 | H11: 981000
B12: 3200000 | C12: =B12/$A$3 -> 0.14222222 | D12: 2264000 | E12: 1624000 | F12: 1280000 | G12: 1088000 | H12: 977000
B13: 3300000 | C13: =B13/$A$3 -> 0.14666667 | D13: 2254000 | E13: 1617000 | F13: 1275000 | G13: 1084000 | H13: 973000
B14: 3400000 | C14: =B14/$A$3 -> 0.15111111 | D14: 2244000 | E14: 1610000 | F14: 1270000 | G14: 1080000 | H14: 969000
B15: 3500000 | C15: =B15/$A$3 -> 0.15555556 | D15: 2234000 | E15: 1603000 | F15: 1265000 | G15: 1076000 | H15: 965000
... B78: 9800000 | C78: =B78/$A$3 -> 0.43555556 | D78: 1604000 | E78: 1162000 | F78: 950000 | G78: 824000 | H78: 713000
D79: 1594000 | E79: 1155000 | F79: 945000 | G79: 820000 | H79: 709000
D80: 1584000 | E80: 1148000 | F80: 940000 | G80: 816000 | H80: 705000
D81: 1574000 | E81: 1141000 | F81: 935000 | G81: 812000 | H81: 701000
D82: 1564000 | E82: 1134000 | F82: 930000 | G82: 808000 | H82: 697000
D83: 1554000 | E83: 1127000 | F83: 925000 | G83: 804000 | H83: 693000
D84: 1544000 | E84: 1120000 | F84: 920000 | G84: 800000 | H84: 689000
D85: 1534000 | E85: 1113000 | F85: 915000 | G85: 796000 | H85: 685000

Sheet  GENIO ISS  
A1: GENIO ISS | B1: DP | C1: % DP | D1: JANGKA WAKTU
D2: 12 | E2: 18 | F2: 24 | G2: 30 | H2: 36
A3: =OTR!E39 -> 22850000 | B3: 2300000 | C3: =B3/$A$3 -> 0.10065646 | D3: 2395000 | E3: 1718000 | F3: 1348000 | G3: 1143000 | H3: 1030000
B4: 2400000 | C4: =B4/$A$3 -> 0.10503282 | D4: 2385000 | E4: 1711000 | F4: 1343000 | G4: 1139000 | H4: 1026000
B5: 2500000 | C5: =B5/$A$3 -> 0.10940919 | D5: 2375000 | E5: 1704000 | F5: 1338000 | G5: 1135000 | H5: 1022000
B6: 2600000 | C6: =B6/$A$3 -> 0.11378556 | D6: 2365000 | E6: 1697000 | F6: 1333000 | G6: 1131000 | H6: 1018000
B7: 2700000 | C7: =B7/$A$3 -> 0.11816193 | D7: 2355000 | E7: 1690000 | F7: 1328000 | G7: 1127000 | H7: 1014000
B8: 2800000 | C8: =B8/$A$3 -> 0.12253829 | D8: 2345000 | E8: 1683000 | F8: 1323000 | G8: 1123000 | H8: 1010000
B9: 2900000 | C9: =B9/$A$3 -> 0.12691466 | D9: 2335000 | E9: 1676000 | F9: 1318000 | G9: 1119000 | H9: 1006000
B10: 3000000 | C10: =B10/$A$3 -> 0.13129103 | D10: 2325000 | E10: 1669000 | F10: 1313000 | G10: 1115000 | H10: 1002000
B11: 3100000 | C11: =B11/$A$3 -> 0.1356674 | D11: 2315000 | E11: 1662000 | F11: 1308000 | G11: 1111000 | H11: 998000
B12: 3200000 | C12: =B12/$A$3 -> 0.14004376 | D12: 2305000 | E12: 1655000 | F12: 1303000 | G12: 1107000 | H12: 994000
